ubuntu.ubuntu.virtualbox.org
*** Found local files:
***   * /home/hadoop/airflow/logs/dag_id=dag1/run_id=manual__2024-02-08T12:00:21.528633+00:00/task_id=fetch_raw_data/attempt=1.log
[2024-02-08, 12:00:23 UTC] {taskinstance.py:1957} INFO - Dependencies all met for dep_context=non-requeueable deps ti=<TaskInstance: dag1.fetch_raw_data manual__2024-02-08T12:00:21.528633+00:00 [queued]>
[2024-02-08, 12:00:23 UTC] {taskinstance.py:1957} INFO - Dependencies all met for dep_context=requeueable deps ti=<TaskInstance: dag1.fetch_raw_data manual__2024-02-08T12:00:21.528633+00:00 [queued]>
[2024-02-08, 12:00:23 UTC] {taskinstance.py:2171} INFO - Starting attempt 1 of 1
[2024-02-08, 12:00:23 UTC] {taskinstance.py:2192} INFO - Executing <Task(BashOperator): fetch_raw_data> on 2024-02-08 12:00:21.528633+00:00
[2024-02-08, 12:00:23 UTC] {standard_task_runner.py:60} INFO - Started process 32967 to run task
[2024-02-08, 12:00:23 UTC] {standard_task_runner.py:87} INFO - Running: ['airflow', 'tasks', 'run', 'dag1', 'fetch_raw_data', 'manual__2024-02-08T12:00:21.528633+00:00', '--job-id', '8', '--raw', '--subdir', 'DAGS_FOLDER/dag1.py', '--cfg-path', '/tmp/tmpvi_qnozg']
[2024-02-08, 12:00:23 UTC] {standard_task_runner.py:88} INFO - Job 8: Subtask fetch_raw_data
[2024-02-08, 12:00:23 UTC] {task_command.py:423} INFO - Running <TaskInstance: dag1.fetch_raw_data manual__2024-02-08T12:00:21.528633+00:00 [running]> on host ubuntu.ubuntu.virtualbox.org
[2024-02-08, 12:00:23 UTC] {taskinstance.py:2481} INFO - Exporting env vars: AIRFLOW_CTX_DAG_OWNER='airflow' AIRFLOW_CTX_DAG_ID='dag1' AIRFLOW_CTX_TASK_ID='fetch_raw_data' AIRFLOW_CTX_EXECUTION_DATE='2024-02-08T12:00:21.528633+00:00' AIRFLOW_CTX_TRY_NUMBER='1' AIRFLOW_CTX_DAG_RUN_ID='manual__2024-02-08T12:00:21.528633+00:00'
[2024-02-08, 12:00:23 UTC] {subprocess.py:63} INFO - Tmp dir root location: /tmp
[2024-02-08, 12:00:23 UTC] {subprocess.py:75} INFO - Running command: ['/usr/bin/bash', '-c', 'python3 /home/hadoop/Bureau/ECBD/scripts/fetch_raw_data.py']
[2024-02-08, 12:00:23 UTC] {subprocess.py:86} INFO - Output:
[2024-02-08, 12:00:36 UTC] {subprocess.py:93} INFO - Warning: Your Kaggle API key is readable by other users on this system! To fix this, you can run 'chmod 600 /home/hadoop/.kaggle/kaggle.json'
[2024-02-08, 12:00:36 UTC] {subprocess.py:93} INFO - Running system command: hdfs dfsadmin -report
[2024-02-08, 12:00:36 UTC] {subprocess.py:93} INFO - HDFS is running.
[2024-02-08, 12:00:36 UTC] {subprocess.py:93} INFO - Warning: Your Kaggle API key is readable by other users on this system! To fix this, you can run 'chmod 600 /home/hadoop/.kaggle/kaggle.json'
[2024-02-08, 12:00:36 UTC] {subprocess.py:93} INFO - Downloading dataset...
[2024-02-08, 12:00:36 UTC] {subprocess.py:93} INFO - Dataset downloaded and extracted.
[2024-02-08, 12:00:36 UTC] {subprocess.py:93} INFO - Running system command: hdfs dfs -rm -r /user/hadoop/amazon/raw_products/amz_ca_total_products_data_processed.csv
[2024-02-08, 12:00:36 UTC] {subprocess.py:93} INFO - Uploading to HDFS...
[2024-02-08, 12:00:36 UTC] {subprocess.py:93} INFO - Running system command: hdfs dfs -put /home/hadoop/Bureau/raw/amz_ca_total_products_data_processed.csv /user/hadoop/amazon/raw_products/amz_ca_total_products_data_processed.csv
[2024-02-08, 12:00:36 UTC] {subprocess.py:93} INFO - Upload completed.
[2024-02-08, 12:00:36 UTC] {subprocess.py:97} INFO - Command exited with return code 0
[2024-02-08, 12:00:36 UTC] {taskinstance.py:1138} INFO - Marking task as SUCCESS. dag_id=dag1, task_id=fetch_raw_data, execution_date=20240208T120021, start_date=20240208T120023, end_date=20240208T120036
[2024-02-08, 12:00:36 UTC] {local_task_job_runner.py:234} INFO - Task exited with return code 0
[2024-02-08, 12:00:36 UTC] {taskinstance.py:3281} INFO - 1 downstream tasks scheduled from follow-on schedule check

